Workbook

Sheet Main
B2: Завдання. (у першому рядку приклад для заповнення)
B3: 1. Перенесіть у стовпці D та E імена та по батькові співробітників зі стовпця C, у стовпці C залиште лише прізвище. | L3: Таблиця 2.
B4: 2. У стовпці G вкажіть гендерну приналежність працівників. | K4: № | L4: Показник | P4: Значення
B5: 3. У стовпці H вкажіть вік працівників на дату прийому на роботу (кількість повних років). | K5: 1 | L5: Кількість працюючих на дату звіту | P5: =COUNTBLANK(L18:L117) -> 39
B6: 4. У стовпці I вкажіть, чи досяг працівник пенсійного віку на момент прийому на роботу, якщо пенсійний вік становить 60 років. | K6: 2 | L6: Кількість звільнених на дату звіту | P6: =COUNTIF(L18:L117,"<="&F14) -> 61
K7: 3 | L7: Кількість звільнених на: | N7: 39814 | P7: =COUNTIF(L18:L117,"<="&N7) -> 3
B8: 5. Заповніть стовпець L; якщо в стовпці K дата звільнення відсутня, то розрахуйте стаж на дату звіту (клітинка F14). | K8: 4 | L8: Середній вік звільнених | P8: =AVERAGEIF(L18:L117,">0",Q18:Q117) -> 51.032787
B9: 6. Налаштуйте сортування Таблиці 1 за Відділом, Прізвищем. | K9: 5 | L9: Працівників якої статі більше звільнили | P9: =IF(COUNTIFS(G18:G117,"чоловіча",L18:L117,"<>")>COUNTIFS(G18:G117,"жіноча",L18:L117,"<>"),"чоловіча",IF(COUNTIFS(G18:G117,"чоловіча",L18:L117,"<>")<COUNTIFS(G18:G117,"жіноча",L18:L117,"<>"),"жіноча","однаково")) -> чоловіча
B10: 7. Додайте стовпець "Відділ", в який додайте відповідні значення для кожного співробітника з аркуша "Відділи". | K10: 6 | L10: Кількість співробітників із прізвищем, яке починається на "Р" | P10: =COUNTIF(C18:C117,"Р*") -> 4
B11: 8. Заповніть в Таблиці 2 стовпець "Значення" за допомогою формул. | K11: 7 | L11: Кількість причин звільнення | P11: =COUNTA(Аркуш1!A4:A9) -> 6
K12: 8 | L12: Найчастіша причина звільнення | P12: =INDEX(Аркуш1!A4:A9,MATCH(MAX(Аркуш1!B4:B9),Аркуш1!B4:B9,0),1) -> за власним бажанням
C14: Таблиця 1. Звіт про стаж роботи співробітників, в тому числі звільнених на | F14: 44927
B16: № | C16: ПІБ співробітника | F16: Дата народження | G16: Стать | H16: Відділ | I16: Вік на момент прийому на роботу | J16: Пенсійний вік | K16: Дата прийому на роботу | L16: Дата звільнення | M16: Стаж | N16: Причина звільнення
C17: Прізвище | D17: Ім'я | E17: По батькові
B18: 1 | C18: ВЕЛИЧКО | D18: САМІЙЛО | E18: ВАСИЛЬОВИЧ | F18: 23575 | G18: =IF(ISNUMBER(SEARCH("вна",E18)),"жіноча","чоловіча") -> чоловіча | H18: =VLOOKUP(_xlfn.CONCAT(C18," ",D18," ",E18),Відділи!B100:C199,2,FALSE) -> Бухгалтерія | I18: =DATEDIF(F18,K18,"Y") -> 42 | J18: =IF(I18>=60,"так","ні") -> ні | K18: 39161 | M18: =IF(L18="",_xlfn.CONCAT(DATEDIF(K18,$F$14,"Y"),"р.", DATEDIF(K18,$F$14,"ym"),"м.", DATEDIF(K18,$F$14,"md"),"д."),_xlfn.CONCAT(DATEDIF(K18,L18,"Y"),"р.", DATEDIF(K18,L18,"ym"),"м.", DATEDIF(K18,L18,"md"),"д.")) -> 15р.9м.12д. | Q18: =DATEDIF(F18,$F$14,"Y") -> 58
B19: 2 | C19: ГОНЧАРЕНКО | D19: НІНА | E19: ІВАНІВНА | F19: 28873 | G19: =IF(ISNUMBER(SEARCH("вна",E19)),"жіноча","чоловіча") -> жіноча | H19: =VLOOKUP(_xlfn.CONCAT(C19," ",D19," ",E19),Відділи!B49:C148,2,FALSE) -> Бухгалтерія | I19: =DATEDIF(F19,K19,"Y") -> 34 | J19: =IF(I19>=60,"так","ні") -> ні | K19: 41402 | M19: =IF(L19="",_xlfn.CONCAT(DATEDIF(K19,$F$14,"Y"),"р.", DATEDIF(K19,$F$14,"ym"),"м.", DATEDIF(K19,$F$14,"md"),"д."),_xlfn.CONCAT(DATEDIF(K19,L19,"Y"),"р.", DATEDIF(K19,L19,"ym"),"м.", DATEDIF(K19,L19,"md"),"д.")) -> 9р.7м.24д. | Q19: =DATEDIF(F19,$F$14,"Y") -> 43
B20: 3 | C20: ІВАНОВА | D20: АНТОНІНА | E20: МИКОЛАЇВНА | F20: 22028 | G20: =IF(ISNUMBER(SEARCH("вна",E20)),"жіноча","чоловіча") -> жіноча | H20: =VLOOKUP(_xlfn.CONCAT(C20," ",D20," ",E20),Відділи!B14:C113,2,FALSE) -> Бухгалтерія | I20: =DATEDIF(F20,K20,"Y") -> 54 | J20: =IF(I20>=60,"так","ні") -> ні | K20: 41977 | M20: =IF(L20="",_xlfn.CONCAT(DATEDIF(K20,$F$14,"Y"),"р.", DATEDIF(K20,$F$14,"ym"),"м.", DATEDIF(K20,$F$14,"md"),"д."),_xlfn.CONCAT(DATEDIF(K20,L20,"Y"),"р.", DATEDIF(K20,L20,"ym"),"м.", DATEDIF(K20,L20,"md"),"д.")) -> 8р.0м.28д. | Q20: =DATEDIF(F20,$F$14,"Y") -> 62
B21: 4 | C21: КОВАЛЬ | D21: ОЛЕКСАНДР | E21: ІВАНОВИЧ | F21: 24302 | G21: =IF(ISNUMBER(SEARCH("вна",E21)),"жіноча","чоловіча") -> чоловіча | H21: =VLOOKUP(_xlfn.CONCAT(C21," ",D21," ",E21),Відділи!B10:C109,2,FALSE) -> Бухгалтерія | I21: =DATEDIF(F21,K21,"Y") -> 46 | J21: =IF(I21>=60,"так","ні") -> ні | K21: 41434 | M21: =IF(L21="",_xlfn.CONCAT(DATEDIF(K21,$F$14,"Y"),"р.", DATEDIF(K21,$F$14,"ym"),"м.", DATEDIF(K21,$F$14,"md"),"д."),_xlfn.CONCAT(DATEDIF(K21,L21,"Y"),"р.", DATEDIF(K21,L21,"ym"),"м.", DATEDIF(K21,L21,"md"),"д.")) -> 9р.6м.23д. | Q21: =DATEDIF(F21,$F$14,"Y") -> 56
B22: 5 | C22: КОВТУН | D22: ІЛЛЯ | E22: ЮРІЙОВИЧ | F22: 17062 | G22: =IF(ISNUMBER(SEARCH("вна",E22)),"жіноча","чоловіча") -> чоловіча | H22: =VLOOKUP(_xlfn.CONCAT(C22," ",D22," ",E22),Відділи!B63:C162,2,FALSE) -> Бухгалтерія | I22: =DATEDIF(F22,K22,"Y") -> 63 | J22: =IF(I22>=60,"так","ні") -> так | K22: 40409 | M22: =IF(L22="",_xlfn.CONCAT(DATEDIF(K22,$F$14,"Y"),"р.", DATEDIF(K22,$F$14,"ym"),"м.", DATEDIF(K22,$F$14,"md"),"д."),_xlfn.CONCAT(DATEDIF(K22,L22,"Y"),"р.", DATEDIF(K22,L22,"ym"),"м.", DATEDIF(K22,L22,"md"),"д.")) -> 12р.4м.13д. | Q22: =DATEDIF(F22,$F$14,"Y") -> 76
B23: 6 | C23: ЛИТВИНЕНКО | D23: МАРІЯ | E23: ІВАНІВНА | F23: 23927 | G23: =IF(ISNUMBER(SEARCH("вна",E23)),"жіноча","чоловіча") -> жіноча | H23: =VLOOKUP(_xlfn.CONCAT(C23," ",D23," ",E23),Відділи!B47:C146,2,FALSE) -> Бухгалтерія | I23: =DATEDIF(F23,K23,"Y") -> 44 | J23: =IF(I23>=60,"так","ні") -> ні | K23: 40122 | M23: =IF(L23="",_xlfn.CONCAT(DATEDIF(K23,$F$14,"Y"),"р.", DATEDIF(K23,$F$14,"ym"),"м.", DATEDIF(K23,$F$14,"md"),"д."),_xlfn.CONCAT(DATEDIF(K23,L23,"Y"),"р.", DATEDIF(K23,L23,"ym"),"м.", DATEDIF(K23,L23,"md"),"д.")) -> 13р.1м.27д. | Q23: =DATEDIF(F23,$F$14,"Y") -> 57
B24: 7 | C24: МАКАРЕНКО | D24: АНТОН | E24: СЕМЕНОВИЧ | F24: 33375 | G24: =IF(ISNUMBER(SEARCH("вна",E24)),"жіноча","чоловіча") -> чоловіча | H24: =VLOOKUP(_xlfn.CONCAT(C24," ",D24," ",E24),Відділи!B78:C177,2,FALSE) -> Бухгалтерія | I24: =DATEDIF(F24,K24,"Y") -> 21 | J24: =IF(I24>=60,"так","ні") -> ні | K24: 41178 | L24: 43312 | M24: =IF(L24="",_xlfn.CONCAT(DATEDIF(K24,$F$14,"Y"),"р.", DATEDIF(K24,$F$14,"ym"),"м.", DATEDIF(K24,$F$14,"md"),"д."),_xlfn.CONCAT(DATEDIF(K24,L24,"Y"),"р.", DATEDIF(K24,L24,"ym"),"м.", DATEDIF(K24,L24,"md"),"д.")) -> 5р.10м.5д. | N24: за власним бажанням | Q24: =DATEDIF(F24,$F$14,"Y") -> 31
B25: 8 | C25: МАРЧУК | D25: ЄВГЕН | E25: КИРИЛОВИЧ | F25: 29020 | G25: =IF(ISNUMBER(SEARCH("вна",E25)),"жіноча","чоловіча") -> чоловіча | H25: =VLOOKUP(_xlfn.CONCAT(C25," ",D25," ",E25),Відділи!B85:C184,2,FALSE) -> Бухгалтерія | I25: =DATEDIF(F25,K25,"Y") -> 32 | J25: =IF(I25>=60,"так","ні") -> ні | K25: 40825 | L25: 42579 | M25: =IF(L25="",_xlfn.CONCAT(DATEDIF(K25,$F$14,"Y"),"р.", DATEDIF(K25,$F$14,"ym"),"м.", DATEDIF(K25,$F$14,"md"),"д."),_xlfn.CONCAT(DATEDIF(K25,L25,"Y"),"р.", DATEDIF(K25,L25,"ym"),"м.", DATEDIF(K25,L25,"md"),"д.")) -> 4р.9м.19д. | N25: за власним бажанням | Q25: =DATEDIF(F25,$F$14,"Y") -> 43
B26: 9 | C26: Мельник | D26: Андрій | E26: Андрійович | F26: 21956 | G26: =IF(ISNUMBER(SEARCH("вна",E26)),"жіноча","чоловіча") -> чоловіча | H26: =VLOOKUP(_xlfn.CONCAT(C26," ",D26," ",E26),Відділи!B2:C101,2,FALSE) -> Бухгалтерія | I26: =DATEDIF(F26,K26,"Y") -> 53 | J26: =IF(I26>=60,"так","ні") -> ні | K26: 41530 | M26: =IF(L26="",_xlfn.CONCAT(DATEDIF(K26,$F$14,"Y"),"р.", DATEDIF(K26,$F$14,"ym"),"м.", DATEDIF(K26,$F$14,"md"),"д."),_xlfn.CONCAT(DATEDIF(K26,L26,"Y"),"р.", DATEDIF(K26,L26,"ym"),"м.", DATEDIF(K26,L26,"md"),"д.")) -> 9р.3м.19д. | Q26: =DATEDIF(F26,$F$14,"Y") -> 62
B27: 10 | C27: МЕЛЬНИЧУК | D27: ЛЮДМИЛА | E27: ОЛЕКСАНДРІВНА | F27: 24224 | G27: =IF(ISNUMBER(SEARCH("вна",E27)),"жіноча","чоловіча") -> жіноча | H27: =VLOOKUP(_xlfn.CONCAT(C27," ",D27," ",E27),Відділи!B37:C136,2,FALSE) -> Бухгалтерія | I27: =DATEDIF(F27,K27,"Y") -> 45 | J27: =IF(I27>=60,"так","ні") -> ні | K27: 40953 | L27: 43891 | M27: =IF(L27="",_xlfn.CONCAT(DATEDIF(K27,$F$14,"Y"),"р.", DATEDIF(K27,$F$14,"ym"),"м.", DATEDIF(K27,$F$14,"md"),"д."),_xlfn.CONCAT(DATEDIF(K27,L27,"Y"),"р.", DATEDIF(K27,L27,"ym"),"м.", DATEDIF(K27,L27,"md"),"д.")) -> 8р.0м.16д. | N27: порушення трудового договору | Q27: =DATEDIF(F27,$F$14,"Y") -> 56
B28: 11 | C28: МОРОЗ | D28: ОЛЕКСАНДР | E28: ОЛЕКСАНДРОВИЧ | F28: 21196 | G28: =IF(ISNUMBER(SEARCH("вна",E28)),"жіноча","чоловіча") -> чоловіча | H28: =VLOOKUP(_xlfn.CONCAT(C28," ",D28," ",E28),Відділи!B20:C119,2,FALSE) -> Бухгалтерія | I28: =DATEDIF(F28,K28,"Y") -> 54 | J28: =IF(I28>=60,"так","ні") -> ні | K28: 40921 | L28: 44494 | M28: =IF(L28="",_xlfn.CONCAT(DATEDIF(K28,$F$14,"Y"),"р.", DATEDIF(K28,$F$14,"ym"),"м.", DATEDIF(K28,$F$14,"md"),"д."),_xlfn.CONCAT(DATEDIF(K28,L28,"Y"),"р.", DATEDIF(K28,L28,"ym"),"м.", DATEDIF(K28,L28,"md"),"д.")) -> 9р.9м.12д. | N28: за згодою сторін | Q28: =DATEDIF(F28,$F$14,"Y") -> 64
B29: 12 | C29: НАЗАРЕНКО | D29: СЕРГІЙ | E29: ЮРІЙОВИЧ | F29: 30614 | G29: =IF(ISNUMBER(SEARCH("вна",E29)),"жіноча","чоловіча") -> чоловіча | H29: =VLOOKUP(_xlfn.CONCAT(C29," ",D29," ",E29),Відділи!B56:C155,2,FALSE) -> Бухгалтерія | I29: =DATEDIF(F29,K29,"Y") -> 29 | J29: =IF(I29>=60,"так","ні") -> ні | K29: 41370 | L29: 41645 | M29: =IF(L29="",_xlfn.CONCAT(DATEDIF(K29,$F$14,"Y"),"р.", DATEDIF(K29,$F$14,"ym"),"м.", DATEDIF(K29,$F$14,"md"),"д."),_xlfn.CONCAT(DATEDIF(K29,L29,"Y"),"р.", DATEDIF(K29,L29,"ym"),"м.", DATEDIF(K29,L29,"md"),"д.")) -> 0р.9м.0д. | N29: за власним бажанням | Q29: =DATEDIF(F29,$F$14,"Y") -> 39
B30: 13 | C30: ПАВЛЮК | D30: ПАВЛО | E30: МИХНОВИЧ | F30: 15594 | G30: =IF(ISNUMBER(SEARCH("вна",E30)),"жіноча","чоловіча") -> чоловіча | H30: =VLOOKUP(_xlfn.CONCAT(C30," ",D30," ",E30),Відділи!B45:C144,2,FALSE) -> Бухгалтерія | I30: =DATEDIF(F30,K30,"Y") -> 70 | J30: =IF(I30>=60,"так","ні") -> так | K30: 41466 | M30: =IF(L30="",_xlfn.CONCAT(DATEDIF(K30,$F$14,"Y"),"р.", DATEDIF(K30,$F$14,"ym"),"м.", DATEDIF(K30,$F$14,"md"),"д."),_xlfn.CONCAT(DATEDIF(K30,L30,"Y"),"р.", DATEDIF(K30,L30,"ym"),"м.", DATEDIF(K30,L30,"md"),"д.")) -> 9р.5м.21д. | Q30: =DATEDIF(F30,$F$14,"Y") -> 80
B31: 14 | C31: РУДЕНКО | D31: БЕЛА | E31: АНДРІЇВНА | F31: 34241 | G31: =IF(ISNUMBER(SEARCH("вна",E31)),"жіноча","чоловіча") -> жіноча | H31: =VLOOKUP(_xlfn.CONCAT(C31," ",D31," ",E31),Відділи!B19:C118,2,FALSE) -> Бухгалтерія | I31: =DATEDIF(F31,K31,"Y") -> 17 | J31: =IF(I31>=60,"так","ні") -> ні | K31: 40601 | L31: 43800 | M31: =IF(L31="",_xlfn.CONCAT(DATEDIF(K31,$F$14,"Y"),"р.", DATEDIF(K31,$F$14,"ym"),"м.", DATEDIF(K31,$F$14,"md"),"д."),_xlfn.CONCAT(DATEDIF(K31,L31,"Y"),"р.", DATEDIF(K31,L31,"ym"),"м.", DATEDIF(K31,L31,"md"),"д.")) -> 8р.9м.4д. | N31: завершення трудового договору | Q31: =DATEDIF(F31,$F$14,"Y") -> 29
B32: 15 | C32: ШУЛЬГА | D32: АНАСТАСІЯ | E32: ОЛЕКСАНДРІВНА | F32: 24140 | G32: =IF(ISNUMBER(SEARCH("вна",E32)),"жіноча","чоловіча") -> жіноча | H32: =VLOOKUP(_xlfn.CONCAT(C32," ",D32," ",E32),Відділи!B98:C197,2,FALSE) -> Бухгалтерія | I32: =DATEDIF(F32,K32,"Y") -> 45 | J32: =IF(I32>=60,"так","ні") -> ні | K32: 40761 | M32: =IF(L32="",_xlfn.CONCAT(DATEDIF(K32,$F$14,"Y"),"р.", DATEDIF(K32,$F$14,"ym"),"м.", DATEDIF(K32,$F$14,"md"),"д."),_xlfn.CONCAT(DATEDIF(K32,L32,"Y"),"р.", DATEDIF(K32,L32,"ym"),"м.", DATEDIF(K32,L32,"md"),"д.")) -> 11р.4м.26д. | Q32: =DATEDIF(F32,$F$14,"Y") -> 56
B33: 16 | C33: ЮРЧЕНКО | D33: АНАТОЛІЙ | E33: ПЕТРОВИЧ | F33: 24595 | G33: =IF(ISNUMBER(SEARCH("вна",E33)),"жіноча","чоловіча") -> чоловіча | H33: =VLOOKUP(_xlfn.CONCAT(C33," ",D33," ",E33),Відділи!B41:C140,2,FALSE) -> Бухгалтерія | I33: =DATEDIF(F33,K33,"Y") -> 44 | J33: =IF(I33>=60,"так","ні") -> ні | K33: 40889 | L33: 44112 | M33: =IF(L33="",_xlfn.CONCAT(DATEDIF(K33,$F$14,"Y"),"р.", DATEDIF(K33,$F$14,"ym"),"м.", DATEDIF(K33,$F$14,"md"),"д."),_xlfn.CONCAT(DATEDIF(K33,L33,"Y"),"р.", DATEDIF(K33,L33,"ym"),"м.", DATEDIF(K33,L33,"md"),"д.")) -> 8р.9м.26д. | N33: завершення трудового договору | Q33: =DATEDIF(F33,$F$14,"Y") -> 55
B34: 17 | C34: БОЙКО | D34: ЮРІЙ | E34: АНАТОЛІЙОВИЧ | F34: 32924 | G34: =IF(ISNUMBER(SEARCH("вна",E34)),"жіноча","чоловіча") -> чоловіча | H34: =VLOOKUP(_xlfn.CONCAT(C34," ",D34," ",E34),Відділи!B6:C105,2,FALSE) -> Відділ збуту | I34: =DATEDIF(F34,K34,"Y") -> 19 | J34: =IF(I34>=60,"так","ні") -> ні | K34: 40058 | M34: =IF(L34="",_xlfn.CONCAT(DATEDIF(K34,$F$14,"Y"),"р.", DATEDIF(K34,$F$14,"ym"),"м.", DATEDIF(K34,$F$14,"md"),"д."),_xlfn.CONCAT(DATEDIF(K34,L34,"Y"),"р.", DATEDIF(K34,L34,"ym"),"м.", DATEDIF(K34,L34,"md"),"д.")) -> 13р.3м.30д. | Q34: =DATEDIF(F34,$F$14,"Y") -> 32
B35: 18 | C35: ВОВК | D35: ФЕДІР | E35: КІНДРАТОВИЧ | F35: 27582 | G35: =IF(ISNUMBER(SEARCH("вна",E35)),"жіноча","чоловіча") -> чоловіча | H35: =VLOOKUP(_xlfn.CONCAT(C35," ",D35," ",E35),Відділи!B72:C171,2,FALSE) -> Відділ збуту | I35: =DATEDIF(F35,K35,"Y") -> 38 | J35: =IF(I35>=60,"так","ні") -> ні | K35: 41594 | L35: 41773 | M35: =IF(L35="",_xlfn.CONCAT(DATEDIF(K35,$F$14,"Y"),"р.", DATEDIF(K35,$F$14,"ym"),"м.", DATEDIF(K35,$F$14,"md"),"д."),_xlfn.CONCAT(DATEDIF(K35,L35,"Y"),"р.", DATEDIF(K35,L35,"ym"),"м.", DATEDIF(K35,L35,"md"),"д.")) -> 0р.5м.28д. | N35: за згодою сторін | Q35: =DATEDIF(F35,$F$14,"Y") -> 47
B36: 19 | C36: ГОРДІЄНКО | D36: НАТАЛІЯ | E36: ВОЛОДИМИРІВНА | F36: 21594 | G36: =IF(ISNUMBER(SEARCH("вна",E36)),"жіноча","чоловіча") -> жіноча | H36: =VLOOKUP(_xlfn.CONCAT(C36," ",D36," ",E36),Відділи!B95:C194,2,FALSE) -> Відділ збуту | I36: =DATEDIF(F36,K36,"Y") -> 52 | J36: =IF(I36>=60,"так","ні") -> ні | K36: 40665 | L36: 42641 | M36: =IF(L36="",_xlfn.CONCAT(DATEDIF(K36,$F$14,"Y"),"р.", DATEDIF(K36,$F$14,"ym"),"м.", DATEDIF(K36,$F$14,"md"),"д."),_xlfn.CONCAT(DATEDIF(K36,L36,"Y"),"р.", DATEDIF(K36,L36,"ym"),"м.", DATEDIF(K36,L36,"md"),"д.")) -> 5р.4м.26д. | N36: за згодою сторін | Q36: =DATEDIF(F36,$F$14,"Y") -> 63
B37: 20 | C37: ДЕНИСЕНКО | D37: ЛАРИСА | E37: ВОЛОДИМИРІВНА | F37: 24923 | G37: =IF(ISNUMBER(SEARCH("вна",E37)),"жіноча","чоловіча") -> жіноча | H37: =VLOOKUP(_xlfn.CONCAT(C37," ",D37," ",E37),Відділи!B101:C200,2,FALSE) -> Відділ збуту | I37: =DATEDIF(F37,K37,"Y") -> 40 | J37: =IF(I37>=60,"так","ні") -> ні | K37: 39546 | L37: 41320 | M37: =IF(L37="",_xlfn.CONCAT(DATEDIF(K37,$F$14,"Y"),"р.", DATEDIF(K37,$F$14,"ym"),"м.", DATEDIF(K37,$F$14,"md"),"д."),_xlfn.CONCAT(DATEDIF(K37,L37,"Y"),"р.", DATEDIF(K37,L37,"ym"),"м.", DATEDIF(K37,L37,"md"),"д.")) -> 4р.10м.7д. | N37: за власним бажанням | Q37: =DATEDIF(F37,$F$14,"Y") -> 54
B38: 21 | C38: ІВАНОВ | D38: МИКОЛА | E38: КУЗЬМИЧ | F38: 33931 | G38: =IF(ISNUMBER(SEARCH("вна",E38)),"жіноча","чоловіча") -> чоловіча | H38: =VLOOKUP(_xlfn.CONCAT(C38," ",D38," ",E38),Відділи!B26:C125,2,FALSE) -> Відділ збуту | I38: =DATEDIF(F38,K38,"Y") -> 21 | J38: =IF(I38>=60,"так","ні") -> ні | K38: 41690 | M38: =IF(L38="",_xlfn.CONCAT(DATEDIF(K38,$F$14,"Y"),"р.", DATEDIF(K38,$F$14,"ym"),"м.", DATEDIF(K38,$F$14,"md"),"д."),_xlfn.CONCAT(DATEDIF(K38,L38,"Y"),"р.", DATEDIF(K38,L38,"ym"),"м.", DATEDIF(K38,L38,"md"),"д.")) -> 8р.10м.12д. | Q38: =DATEDIF(F38,$F$14,"Y") -> 30
B39: 22 | C39: КОВАЛЬОВА | D39: ІРИНА | E39: ФЕДОРІВНА | F39: 22060 | G39: =IF(ISNUMBER(SEARCH("вна",E39)),"жіноча","чоловіча") -> жіноча | H39: =VLOOKUP(_xlfn.CONCAT(C39," ",D39," ",E39),Відділи!B75:C174,2,FALSE) -> Відділ збуту | I39: =DATEDIF(F39,K39,"Y") -> 51 | J39: =IF(I39>=60,"так","ні") -> ні | K39: 40729 | M39: =IF(L39="",_xlfn.CONCAT(DATEDIF(K39,$F$14,"Y"),"р.", DATEDIF(K39,$F$14,"ym"),"м.", DATEDIF(K39,$F$14,"md"),"д."),_xlfn.CONCAT(DATEDIF(K39,L39,"Y"),"р.", DATEDIF(K39,L39,"ym"),"м.", DATEDIF(K39,L39,"md"),"д.")) -> 11р.5м.27д. | Q39: =DATEDIF(F39,$F$14,"Y") -> 62
B40: 23 | C40: КУШНІР | D40: ІГОР | E40: МИКОЛАЙОВИЧ | F40: 26689 | G40: =IF(ISNUMBER(SEARCH("вна",E40)),"жіноча","чоловіча") -> чоловіча | H40: =VLOOKUP(_xlfn.CONCAT(C40," ",D40," ",E40),Відділи!B46:C145,2,FALSE) -> Відділ збуту | I40: =DATEDIF(F40,K40,"Y") -> 42 | J40: =IF(I40>=60,"так","ні") -> ні | K40: 42041 | M40: =IF(L40="",_xlfn.CONCAT(DATEDIF(K40,$F$14,"Y"),"р.", DATEDIF(K40,$F$14,"ym"),"м.", DATEDIF(K40,$F$14,"md"),"д."),_xlfn.CONCAT(DATEDIF(K40,L40,"Y"),"р.", DATEDIF(K40,L40,"ym"),"м.", DATEDIF(K40,L40,"md"),"д.")) -> 7р.10м.26д. | Q40: =DATEDIF(F40,$F$14,"Y") -> 49
B41: 24 | C41: ЛЕВЧЕНКО | D41: ЮЛІЯ | E41: АНДРІЇВНА | F41: 33220 | G41: =IF(ISNUMBER(SEARCH("вна",E41)),"жіноча","чоловіча") -> жіноча | H41: =VLOOKUP(_xlfn.CONCAT(C41," ",D41," ",E41),Відділи!B31:C130,2,FALSE) -> Відділ збуту | I41: =DATEDIF(F41,K41,"Y") -> 16 | J41: =IF(I41>=60,"так","ні") -> ні | K41: 39417 | M41: =IF(L41="",_xlfn.CONCAT(DATEDIF(K41,$F$14,"Y"),"р.", DATEDIF(K41,$F$14,"ym"),"м.", DATEDIF(K41,$F$14,"md"),"д."),_xlfn.CONCAT(DATEDIF(K41,L41,"Y"),"р.", DATEDIF(K41,L41,"ym"),"м.", DATEDIF(K41,L41,"md"),"д.")) -> 15р.1м.0д. | Q41: =DATEDIF(F41,$F$14,"Y") -> 32
B42: 25 | C42: ЛИСЕНКО | D42: МИКОЛА | E42: ВІТАЛІЙОВИЧ | F42: 18715 | G42: =IF(ISNUMBER(SEARCH("вна",E42)),"жіноча","чоловіча") -> чоловіча | H42: =VLOOKUP(_xlfn.CONCAT(C42," ",D42," ",E42),Відділи!B21:C120,2,FALSE) -> Відділ збуту | I42: =DATEDIF(F42,K42,"Y") -> 64 | J42: =IF(I42>=60,"так","ні") -> так | K42: 42233 | M42: =IF(L42="",_xlfn.CONCAT(DATEDIF(K42,$F$14,"Y"),"р.", DATEDIF(K42,$F$14,"ym"),"м.", DATEDIF(K42,$F$14,"md"),"д."),_xlfn.CONCAT(DATEDIF(K42,L42,"Y"),"р.", DATEDIF(K42,L42,"ym"),"м.", DATEDIF(K42,L42,"md"),"д.")) -> 7р.4м.15д. | Q42: =DATEDIF(F42,$F$14,"Y") -> 71
B43: 26 | C43: МАРТИНЮК | D43: АДАМ | E43: ІВАНОВИЧ | F43: 21994 | G43: =IF(ISNUMBER(SEARCH("вна",E43)),"жіноча","чоловіча") -> чоловіча | H43: =VLOOKUP(_xlfn.CONCAT(C43," ",D43," ",E43),Відділи!B48:C147,2,FALSE) -> Відділ збуту | I43: =DATEDIF(F43,K43,"Y") -> 47 | J43: =IF(I43>=60,"так","ні") -> ні | K43: 39257 | M43: =IF(L43="",_xlfn.CONCAT(DATEDIF(K43,$F$14,"Y"),"р.", DATEDIF(K43,$F$14,"ym"),"м.", DATEDIF(K43,$F$14,"md"),"д."),_xlfn.CONCAT(DATEDIF(K43,L43,"Y"),"р.", DATEDIF(K43,L43,"ym"),"м.", DATEDIF(K43,L43,"md"),"д.")) -> 15р.6м.8д. | Q43: =DATEDIF(F43,$F$14,"Y") -> 62
...

Sheet Відділи
B1: Співробітник | C1: Відділ
B2: МЕЛЬНИК АНДРІЙ АНДРІЙОВИЧ | C2: Бухгалтерія
B3: ШЕВЧЕНКО ТАРАС ГРИГОРОВИЧ | C3: Юридичний відділ
B4: КОВАЛЕНКО АННА МИКОЛАЇВНА | C4: Фінансовий відділ
B5: БОНДАРЕНКО ОЛЕНА АНАТОЛІЇВНА | C5: Маркетинговий відділ
B6: БОЙКО ЮРІЙ АНАТОЛІЙОВИЧ | C6: Відділ збуту
B7: ТКАЧЕНКО ОЛЕКСАНДР МИКОЛАЙОВИЧ | C7: Господарський відділ
B8: КРАВЧЕНКО ВІКТОР АНДРІЙОВИЧ | C8: Дирекція
B9: КОВАЛЬЧУК КИРИЛО СЕРГІЙОВИЧ | C9: Відділ кадрів
B10: КОВАЛЬ ОЛЕКСАНДР ІВАНОВИЧ | C10: Бухгалтерія
B11: ОЛІЙНИК БОРИС ІЛЛІЧ | C11: Фінансовий відділ
B12: ШЕВЧУК СВЯТОСЛАВ ЮРІЙОВИЧ | C12: Господарський відділ
... B101: ДЕНИСЕНКО ЛАРИСА ВОЛОДИМИРІВНА | C101: Відділ збуту

Sheet Аркуш1
A3: Позначки рядків | B3: Кількість з Причина звільнення
A4: за власним бажанням | B4: 25
A5: за згодою сторін | B5: 13
A6: завершення трудового договору | B6: 4
A7: не відповідність | B7: 12
A8: порушення трудового договору | B8: 2
A9: скорочення штату | B9: 5
A10: (пусто)
A11: Загальний підсумок | B11: 61
B13: =INDEX(A4:A9,MATCH(MAX(B4:B9),B4:B9,0),1) -> за власним бажанням
