Workbook
Name Роздільник_Category: #N/A
Name Роздільник_Category1: #N/A
Name Роздільник_Category2: #N/A
Name Роздільник_Segment: #N/A
Name Роздільник_Segment1: #N/A
Name Роздільник_Segment2: #N/A
Name Роздільник_Ship_Mode: #N/A

Sheet Dashboard_Final
C15: Sub Category | D15: 2017 | E15: 2016 | F15: vs PY | H15: Sub Category | I15: 2017 | J15: 2016 | K15: vs PY | M15: Sub Category | N15: 2017 | O15: 2016 | P15: vs PY | R15: Sub Category | S15: 2017 | T15: 2016 | U15: vs PY
C16: =IF(Working!A14=0,"",Working!A14) -> Phones | D16: =IF(Working!B14=0,"",Working!B14) -> 105340.52 | E16: =IF(Working!C14=0,"",Working!C14) -> 78962.03 | F16: =IF(C16="","",D16/E16-1) -> 0.33406545 | H16: =IF(Working!E14=0,"",Working!E14) -> New York City | I16: =IF(Working!F14=0,"",Working!F14) -> 86939.601 | J16: =IF(Working!G14=0,"",Working!G14) -> 54824.098 | K16: =IF(H16="","",I16/J16-1) -> 0.58579173 | M16: =Working!A31 -> Phones | N16: =Working!B31 -> 105340.52 | O16: =Working!C31 -> 78962.03 | P16: =N16/O16-1 -> 0.33406545 | R16: =Working!E31 -> New York City | S16: =Working!F31 -> 86939.601 | T16: =Working!G31 -> 54824.098 | U16: =S16/T16-1 -> 0.58579173
C17: =SUBSTITUTE(Working!A15,0,"") -> Chairs | D17: =IF(Working!B15=0,"",Working!B15) -> 95554.353 | E17: =IF(Working!C15=0,"",Working!C15) -> 83918.645 | F17: =IF(C17="","",D17/E17-1) -> 0.13865462 | H17: =IF(Working!E15=0,"",Working!E15) -> Los Angeles | I17: =IF(Working!F15=0,"",Working!F15) -> 48875.692 | J17: =IF(Working!G15=0,"",Working!G15) -> 56398.748 | K17: =IF(H17="","",I17/J17-1) -> -0.13339047 | M17: =Working!A32 -> Chairs | N17: =Working!B32 -> 95554.353 | O17: =Working!C32 -> 83918.645 | P17: =N17/O17-1 -> 0.13865462 | R17: =Working!E32 -> Los Angeles | S17: =Working!F32 -> 48875.692 | T17: =Working!G32 -> 56398.748 | U17: =S17/T17-1 -> -0.13339047
C18: =SUBSTITUTE(Working!A16,0,"") -> Storage | D18: =IF(Working!B16=0,"",Working!B16) -> 69677.618 | E18: =IF(Working!C16=0,"",Working!C16) -> 58788.7 | F18: =IF(C18="","",D18/E18-1) -> 0.18522128 | H18: =IF(Working!E16=0,"",Working!E16) -> Seattle | I18: =IF(Working!F16=0,"",Working!F16) -> 56990.82 | J18: =IF(Working!G16=0,"",Working!G16) -> 16158.722 | K18: =IF(H18="","",I18/J18-1) -> 2.5269386 | M18: =Working!A33 -> Storage | N18: =Working!B33 -> 69677.618 | O18: =Working!C33 -> 58788.7 | P18: =N18/O18-1 -> 0.18522128 | R18: =Working!E33 -> Seattle | S18: =Working!F33 -> 56990.82 | T18: =Working!G33 -> 16158.722 | U18: =S18/T18-1 -> 2.5269386
C19: =SUBSTITUTE(Working!A17,0,"") -> Binders | D19: =IF(Working!B17=0,"",Working!B17) -> 72788.045 | E19: =IF(Working!C17=0,"",Working!C17) -> 49683.325 | F19: =IF(C19="","",D19/E19-1) -> 0.46503973 | H19: =IF(Working!E17=0,"",Working!E17) -> Philadelphia | I19: =IF(Working!F17=0,"",Working!F17) -> 41595.502 | J19: =IF(Working!G17=0,"",Working!G17) -> 30304.938 | K19: =IF(H19="","",I19/J19-1) -> 0.37256516 | M19: =Working!A34 -> Binders | N19: =Working!B34 -> 72788.045 | O19: =Working!C34 -> 49683.325 | P19: =N19/O19-1 -> 0.46503973 | R19: =Working!E34 -> Philadelphia | S19: =Working!F34 -> 41595.502 | T19: =Working!G34 -> 30304.938 | U19: =S19/T19-1 -> 0.37256516
C20: =SUBSTITUTE(Working!A18,0,"") -> Tables | D20: =IF(Working!B18=0,"",Working!B18) -> 60893.543 | E20: =IF(Working!C18=0,"",Working!C18) -> 60833.2 | F20: =IF(C20="","",D20/E20-1) -> 0.00099192545 | H20: =IF(Working!E18=0,"",Working!E18) -> San Francisco | I20: =IF(Working!F18=0,"",Working!F18) -> 37197.551 | J20: =IF(Working!G18=0,"",Working!G18) -> 29845.871 | K20: =IF(H20="","",I20/J20-1) -> 0.24632151 | M20: =Working!A35 -> Tables | N20: =Working!B35 -> 60893.543 | O20: =Working!C35 -> 60833.2 | P20: =N20/O20-1 -> 0.00099192545 | R20: =Working!E35 -> San Francisco | S20: =Working!F35 -> 37197.551 | T20: =Working!G35 -> 29845.871 | U20: =S20/T20-1 -> 0.24632151
C21: =SUBSTITUTE(Working!A19,0,"") -> Copiers | D21: =IF(Working!B19=0,"",Working!B19) -> 62899.388 | E21: =IF(Working!C19=0,"",Working!C19) -> 49599.41 | F21: =IF(C21="","",D21/E21-1) -> 0.26814791 | H21: =IF(Working!E19=0,"",Working!E19) -> Detroit | I21: =IF(Working!F19=0,"",Working!F19) -> 12148.886 | J21: =IF(Working!G19=0,"",Working!G19) -> 21197.32 | K21: =IF(H21="","",I21/J21-1) -> -0.42686689 | M21: =Working!A36 -> Copiers | N21: =Working!B36 -> 62899.388 | O21: =Working!C36 -> 49599.41 | P21: =N21/O21-1 -> 0.26814791 | R21: =Working!E36 -> Detroit | S21: =Working!F36 -> 12148.886 | T21: =Working!G36 -> 21197.32 | U21: =S21/T21-1 -> -0.42686689
C22: =SUBSTITUTE(Working!A20,0,"") -> Accessories | D22: =IF(Working!B20=0,"",Working!B20) -> 59946.232 | E22: =IF(Working!C20=0,"",Working!C20) -> 41895.854 | F22: =IF(C22="","",D22/E22-1) -> 0.43083924 | H22: =IF(Working!E20=0,"",Working!E20) -> Houston | I22: =IF(Working!F20=0,"",Working!F20) -> 16212.806 | J22: =IF(Working!G20=0,"",Working!G20) -> 16448.681 | K22: =IF(H22="","",I22/J22-1) -> -0.014340055 | M22: =Working!A37 -> Accessories | N22: =Working!B37 -> 59946.232 | O22: =Working!C37 -> 41895.854 | P22: =N22/O22-1 -> 0.43083924 | R22: =Working!E37 -> Houston | S22: =Working!F37 -> 16212.806 | T22: =Working!G37 -> 16448.681 | U22: =S22/T22-1 -> -0.014340055
C23: =SUBSTITUTE(Working!A21,0,"") -> Machines | D23: =IF(Working!B21=0,"",Working!B21) -> 43544.675 | E23: =IF(Working!C21=0,"",Working!C21) -> 55906.886 | F23: =IF(C23="","",D23/E23-1) -> -0.22112144 | H23: =IF(Working!E21=0,"",Working!E21) -> Chicago | I23: =IF(Working!F21=0,"",Working!F21) -> 16245.611 | J23: =IF(Working!G21=0,"",Working!G21) -> 13067.55 | K23: =IF(H23="","",I23/J23-1) -> 0.24320251 | M23: =Working!A38 -> Machines | N23: =Working!B38 -> 43544.675 | O23: =Working!C38 -> 55906.886 | P23: =N23/O23-1 -> -0.22112144 | R23: =Working!E38 -> Chicago | S23: =Working!F38 -> 16245.611 | T23: =Working!G38 -> 13067.55 | U23: =S23/T23-1 -> 0.24320251
C24: =SUBSTITUTE(Working!A22,0,"") -> Appliances | D24: =IF(Working!B22=0,"",Working!B22) -> 42926.932 | E24: =IF(Working!C22=0,"",Working!C22) -> 26050.315 | F24: =IF(C24="","",D24/E24-1) -> 0.64784695 | H24: =IF(Working!E22=0,"",Working!E22) -> Columbus | I24: =IF(Working!F22=0,"",Working!F22) -> 17571.473 | J24: =IF(Working!G22=0,"",Working!G22) -> 9506.412 | K24: =IF(H24="","",I24/J24-1) -> 0.84838118 | M24: =Working!A39 -> Appliances | N24: =Working!B39 -> 42926.932 | O24: =Working!C39 -> 26050.315 | P24: =N24/O24-1 -> 0.64784695 | R24: =Working!E39 -> Columbus | S24: =Working!F39 -> 17571.473 | T24: =Working!G39 -> 9506.412 | U24: =S24/T24-1 -> 0.84838118
C25: =SUBSTITUTE(Working!A23,0,"") -> Furnishings | D25: =IF(Working!B23=0,"",Working!B23) -> 28915.094 | E25: =IF(Working!C23=0,"",Working!C23) -> 27874.124 | F25: =IF(C25="","",D25/E25-1) -> 0.037345389 | H25: =IF(Working!E23=0,"",Working!E23) -> Lafayette | I25: =IF(Working!F23=0,"",Working!F23) -> 5630.51 | J25: =IF(Working!G23=0,"",Working!G23) -> 18431.34 | K25: =IF(H25="","",I25/J25-1) -> -0.69451434 | M25: =Working!A40 -> Furnishings | N25: =Working!B40 -> 28915.094 | O25: =Working!C40 -> 27874.124 | P25: =N25/O25-1 -> 0.037345389 | R25: =Working!E40 -> Lafayette | S25: =Working!F40 -> 5630.51 | T25: =Working!G40 -> 18431.34 | U25: =S25/T25-1 -> -0.69451434
C26: Total | D26: =SUM(D16:D25) -> 642486.4 | E26: =SUM(E16:E25) -> 533512.49 | F26: =IF(C26="","",D26/E26-1) -> 0.20425746 | H26: Total | I26: =SUM(I16:I25) -> 339408.45 | J26: =SUM(J16:J25) -> 266183.68 | K26: =IF(H26="","",I26/J26-1) -> 0.27509114 | M26: Total | N26: =SUM(N16:N25) -> 642486.4 | O26: =SUM(O16:O25) -> 533512.49 | P26: =N26/O26-1 -> 0.20425746 | R26: Total | S26: =SUM(S16:S25) -> 339408.45 | T26: =SUM(T16:T25) -> 266183.68 | U26: =S26/T26-1 -> 0.27509114

Sheet Source_data
A1: Row ID | B1: Order ID | C1: Order Date | D1: Ship Date | E1: Ship Mode | F1: Customer ID | G1: Customer Name | H1: Segment | I1: Country | J1: City | K1: State | L1: Postal Code | M1: Region | N1: Product ID | O1: Category | P1: Sub-Category | Q1: Product Name | R1: Sales | S1: Quantity | T1: Discount | U1: Profit
A2: 1 | B2: CA-2016-152156 | C2: 42682 | D2: 42685 | E2: Second Class | F2: CG-12520 | G2: Claire Gute | H2: Consumer | I2: United States | J2: Henderson | K2: Kentucky | L2: 42420 | M2: South | N2: FUR-BO-10001798 | O2: Furniture | P2: Bookcases | Q2: Bush Somerset Collection Bookcase | R2: 261.96 | S2: 2 | T2: 0 | U2: 41.9136
A3: 2 | B3: CA-2016-152156 | C3: 42682 | D3: 42685 | E3: Second Class | F3: CG-12520 | G3: Claire Gute | H3: Consumer | I3: United States | J3: Henderson | K3: Kentucky | L3: 42420 | M3: South | N3: FUR-CH-10000454 | O3: Furniture | P3: Chairs | Q3: Hon Deluxe Fabric Upholstered Stacking Chairs, Rounded Back | R3: 731.94 | S3: 3 | T3: 0 | U3: 219.582
A4: 3 | B4: CA-2016-138688 | C4: 42533 | D4: 42537 | E4: Second Class | F4: DV-13045 | G4: Darrin Van Huff | H4: Corporate | I4: United States | J4: Los Angeles | K4: California | L4: 90036 | M4: West | N4: OFF-LA-10000240 | O4: Office Supplies | P4: Labels | Q4: Self-Adhesive Address Labels for Typewriters by Universal | R4: 14.62 | S4: 2 | T4: 0 | U4: 6.8714
A5: 4 | B5: US-2015-108966 | C5: 42288 | D5: 42295 | E5: Standard Class | F5: SO-20335 | G5: Sean O'Donnell | H5: Consumer | I5: United States | J5: Fort Lauderdale | K5: Florida | L5: 33311 | M5: South | N5: FUR-TA-10000577 | O5: Furniture | P5: Tables | Q5: Bretford CR4500 Series Slim Rectangular Table | R5: 957.5775 | S5: 5 | T5: 0.45 | U5: -383.031
A6: 5 | B6: US-2015-108966 | C6: 42288 | D6: 42295 | E6: Standard Class | F6: SO-20335 | G6: Sean O'Donnell | H6: Consumer | I6: United States | J6: Fort Lauderdale | K6: Florida | L6: 33311 | M6: South | N6: OFF-ST-10000760 | O6: Office Supplies | P6: Storage | Q6: Eldon Fold 'N Roll Cart System | R6: 22.368 | S6: 2 | T6: 0.2 | U6: 2.5164
A7: 6 | B7: CA-2014-115812 | C7: 41799 | D7: 41804 | E7: Standard Class | F7: BH-11710 | G7: Brosina Hoffman | H7: Consumer | I7: United States | J7: Los Angeles | K7: California | L7: 90032 | M7: West | N7: FUR-FU-10001487 | O7: Furniture | P7: Furnishings | Q7: Eldon Expressions Wood and Plastic Desk Accessories, Cherry Wood | R7: 48.86 | S7: 7 | T7: 0 | U7: 14.1694
A8: 7 | B8: CA-2014-115812 | C8: 41799 | D8: 41804 | E8: Standard Class | F8: BH-11710 | G8: Brosina Hoffman | H8: Consumer | I8: United States | J8: Los Angeles | K8: California | L8: 90032 | M8: West | N8: OFF-AR-10002833 | O8: Office Supplies | P8: Art | Q8: Newell 322 | R8: 7.28 | S8: 4 | T8: 0 | U8: 1.9656
A9: 8 | B9: CA-2014-115812 | C9: 41799 | D9: 41804 | E9: Standard Class | F9: BH-11710 | G9: Brosina Hoffman | H9: Consumer | I9: United States | J9: Los Angeles | K9: California | L9: 90032 | M9: West | N9: TEC-PH-10002275 | O9: Technology | P9: Phones | Q9: Mitel 5320 IP Phone VoIP phone | R9: 907.152 | S9: 6 | T9: 0.2 | U9: 90.7152
A10: 9 | B10: CA-2014-115812 | C10: 41799 | D10: 41804 | E10: Standard Class | F10: BH-11710 | G10: Brosina Hoffman | H10: Consumer | I10: United States | J10: Los Angeles | K10: California | L10: 90032 | M10: West | N10: OFF-BI-10003910 | O10: Office Supplies | P10: Binders | Q10: DXL Angle-View Binders with Locking Rings by Samsill | R10: 18.504 | S10: 3 | T10: 0.2 | U10: 5.7825
A11: 10 | B11: CA-2014-115812 | C11: 41799 | D11: 41804 | E11: Standard Class | F11: BH-11710 | G11: Brosina Hoffman | H11: Consumer | I11: United States | J11: Los Angeles | K11: California | L11: 90032 | M11: West | N11: OFF-AP-10002892 | O11: Office Supplies | P11: Appliances | Q11: Belkin F5C206VTEL 6 Outlet Surge | R11: 114.9 | S11: 5 | T11: 0 | U11: 34.47
A12: 11 | B12: CA-2014-115812 | C12: 41799 | D12: 41804 | E12: Standard Class | F12: BH-11710 | G12: Brosina Hoffman | H12: Consumer | I12: United States | J12: Los Angeles | K12: California | L12: 90032 | M12: West | N12: FUR-TA-10001539 | O12: Furniture | P12: Tables | Q12: Chromcraft Rectangular Conference Tables | R12: 1706.184 | S12: 9 | T12: 0.2 | U12: 85.3092
A13: 12 | B13: CA-2014-115812 | C13: 41799 | D13: 41804 | E13: Standard Class | F13: BH-11710 | G13: Brosina Hoffman | H13: Consumer | I13: United States | J13: Los Angeles | K13: California | L13: 90032 | M13: West | N13: TEC-PH-10002033 | O13: Technology | P13: Phones | Q13: Konftel 250 Conference phone - Charcoal black | R13: 911.424 | S13: 4 | T13: 0.2 | U13: 68.3568
... A9995: 9994 | B9995: CA-2017-119914 | C9995: 42859 | D9995: 42864 | E9995: Second Class | F9995: CC-12220 | G9995: Chris Cortes | H9995: Consumer | I9995: United States | J9995: Westminster | K9995: California | L9995: 92683 | M9995: West | N9995: OFF-AP-10002684 | O9995: Office Supplies | P9995: Appliances | Q9995: Acco 7-Outlet Masterpiece Power Center, Wihtout Fax/Phone Line Protection | R9995: 243.16 | S9995: 2 | T9995: 0 | U9995: 72.948

Sheet Working
A3: Позначки рядків | B3: Сума з Sales | C3: Сума з Profit | E3: Sales vs PY
A4: 2016 | B4: 609205.6 | C4: 81795.174
A5: 2017 | B5: 733215.26 | C5: 93439.27 | E5: =GETPIVOTDATA("Сума з Sales",$A$3,"Роки",2017)/GETPIVOTDATA("Сума з Sales",$A$3,"Роки",2016)-1 -> 0.20355962 | F5: =GETPIVOTDATA("Сума з Profit",$A$3,"Роки",2017)/GETPIVOTDATA("Сума з Profit",$A$3,"Роки",2016)-1 -> 0.14235675
A6: Загальний підсумок | B6: 1342420.9 | C6: 175234.44
A11: Data for table 1 and 2
A12: Сума з Sales | B12: Позначки стовпців | E12: Сума з Sales | F12: Позначки стовпців
A13: Позначки рядків | B13: 2017 | C13: 2016 | E13: Позначки рядків | F13: 2017 | G13: 2016
A14: Phones | B14: 105340.52 | C14: 78962.03 | E14: New York City | F14: 86939.601 | G14: 54824.098
A15: Chairs | B15: 95554.353 | C15: 83918.645 | E15: Los Angeles | F15: 48875.692 | G15: 56398.748
A16: Storage | B16: 69677.618 | C16: 58788.7 | E16: Seattle | F16: 56990.82 | G16: 16158.722
A17: Binders | B17: 72788.045 | C17: 49683.325 | E17: Philadelphia | F17: 41595.502 | G17: 30304.938
A18: Tables | B18: 60893.543 | C18: 60833.2 | E18: San Francisco | F18: 37197.551 | G18: 29845.871
A19: Copiers | B19: 62899.388 | C19: 49599.41 | E19: Detroit | F19: 12148.886 | G19: 21197.32
A20: Accessories | B20: 59946.232 | C20: 41895.854 | E20: Houston | F20: 16212.806 | G20: 16448.681
A21: Machines | B21: 43544.675 | C21: 55906.886 | E21: Chicago | F21: 16245.611 | G21: 13067.55
A22: Appliances | B22: 42926.932 | C22: 26050.315 | E22: Columbus | F22: 17571.473 | G22: 9506.412
A23: Furnishings | B23: 28915.094 | C23: 27874.124 | E23: Lafayette | F23: 5630.51 | G23: 18431.34
A28: Data for table 3 and 4
A29: Сума з Sales | B29: Позначки стовпців | E29: Сума з Sales | F29: Позначки стовпців
A30: Позначки рядків | B30: 2017 | C30: 2016 | E30: Позначки рядків | F30: 2017 | G30: 2016
A31: Phones | B31: 105340.52 | C31: 78962.03 | E31: New York City | F31: 86939.601 | G31: 54824.098
A32: Chairs | B32: 95554.353 | C32: 83918.645 | E32: Los Angeles | F32: 48875.692 | G32: 56398.748
A33: Storage | B33: 69677.618 | C33: 58788.7 | E33: Seattle | F33: 56990.82 | G33: 16158.722
A34: Binders | B34: 72788.045 | C34: 49683.325 | E34: Philadelphia | F34: 41595.502 | G34: 30304.938
A35: Tables | B35: 60893.543 | C35: 60833.2 | E35: San Francisco | F35: 37197.551 | G35: 29845.871
A36: Copiers | B36: 62899.388 | C36: 49599.41 | E36: Detroit | F36: 12148.886 | G36: 21197.32
A37: Accessories | B37: 59946.232 | C37: 41895.854 | E37: Houston | F37: 16212.806 | G37: 16448.681
A38: Machines | B38: 43544.675 | C38: 55906.886 | E38: Chicago | F38: 16245.611 | G38: 13067.55
A39: Appliances | B39: 42926.932 | C39: 26050.315 | E39: Columbus | F39: 17571.473 | G39: 9506.412
A40: Furnishings | B40: 28915.094 | C40: 27874.124 | E40: Lafayette | F40: 5630.51 | G40: 18431.34
A41: Загальний підсумок | B41: 642486.4 | C41: 533512.49 | E41: Загальний підсумок | F41: 339408.45 | G41: 266183.68
A43: Data for chart 1
A45: Роки | B45: Квартали | C45: Сума з Sales | D45: Сума з Quantity | H45: Sales | I45: Quantity | J45: Price
A46: 2014 | B46: Кв.1 | C46: 74447.796 | D46: 1028 | F46: =A46 -> 2014 | G46: =B46 -> Кв.1 | H46: =C46 -> 74447.796 | I46: =D46 -> 1028 | J46: =H46/I46 -> 72.420035
B47: Кв.2 | C47: 86538.76 | D47: 1523 | G47: =B47 -> Кв.2 | H47: =C47 -> 86538.76 | I47: =D47 -> 1523 | J47: =H47/I47 -> 56.821247
B48: Кв.3 | C48: 143633.21 | D48: 2159 | G48: =B48 -> Кв.3 | H48: =C48 -> 143633.21 | I48: =D48 -> 2159 | J48: =H48/I48 -> 66.527657
B49: Кв.4 | C49: 179627.73 | D49: 2871 | G49: =B49 -> Кв.4 | H49: =C49 -> 179627.73 | I49: =D49 -> 2871 | J49: =H49/I49 -> 62.566259
A50: 2015 | B50: Кв.1 | C50: 68851.739 | D50: 990 | F50: =A50 -> 2015 | G50: =B50 -> Кв.1 | H50: =C50 -> 68851.739 | I50: =D50 -> 990 | J50: =H50/I50 -> 69.547211
B51: Кв.2 | C51: 89124.187 | D51: 1604 | G51: =B51 -> Кв.2 | H51: =C51 -> 89124.187 | I51: =D51 -> 1604 | J51: =H51/I51 -> 55.563708
B52: Кв.3 | C52: 130259.58 | D52: 2241 | G52: =B52 -> Кв.3 | H52: =C52 -> 130259.58 | I52: =D52 -> 2241 | J52: =H52/I52 -> 58.125647
...

Sheet Dashboard_Wireframe
B3: Logo | I3: Filter buttons | S3: Filter buttons
D7: Text box 1 | H7: Text box 2 | L7: Text box 3 | P7: Text box 4 | T7: Text box 5 | X7: Text box 6
F13: Filter buttons | R13: Filter buttons
E20: Table 1 | K20: Table 2 | Q20: Table 3 | W20: Table 4
F32: Filter buttons | N32: Filter buttons | U32: Filter buttons
F39: Chart 1 | S39: Chart 2
